2025-09-29 07:07:44,849 - FacebookBot - INFO - [main.py:846] - üé™ Facebook Marketplace Bot Starting...
2025-09-29 07:07:45,312 - FacebookBot - INFO - [main.py:95] - ‚úÖ Database setup completed successfully
2025-09-29 07:07:45,532 - FacebookBot - INFO - [main.py:33] - ü§ñ Facebook Marketplace Bot Initialized
2025-09-29 07:07:45,535 - FacebookBot - INFO - [main.py:799] - üöÄ Starting Facebook Bot Cycle
2025-09-29 07:07:45,651 - FacebookBot - INFO - [main.py:137] - üîß Running in headless mode
2025-09-29 07:07:52,077 - FacebookBot - INFO - [main.py:168] - ‚úÖ WebDriver initialized successfully
2025-09-29 07:07:54,128 - FacebookBot - INFO - [main.py:240] - üîê Login attempt 1/3
2025-09-29 07:08:12,224 - urllib3.connectionpool - WARNING - [connectionpool.py:868] - Retrying (Retry(total=2, connect=None, read=None, redirect=None, status=None)) after connection broken by 'ConnectionResetError(10054, 'An existing connection was forcibly closed by the remote host', None, 10054, None)': /session/53ac4d4a784d7d1a802a82e01dcbf8b1
2025-09-29 07:08:16,280 - urllib3.connectionpool - WARNING - [connectionpool.py:868] - Retrying (Retry(total=1, connect=None, read=None, redirect=None, status=None)) after connection broken by 'NewConnectionError('<urllib3.connection.HTTPConnection object at 0x000002189F60C050>: Failed to establish a new connection: [WinError 10061] No connection could be made because the target machine actively refused it')': /session/53ac4d4a784d7d1a802a82e01dcbf8b1
2025-09-29 07:08:20,377 - urllib3.connectionpool - WARNING - [connectionpool.py:868] - Retrying (Retry(total=0, connect=None, read=None, redirect=None, status=None)) after connection broken by 'NewConnectionError('<urllib3.connection.HTTPConnection object at 0x000002189F60C550>: Failed to establish a new connection: [WinError 10061] No connection could be made because the target machine actively refused it')': /session/53ac4d4a784d7d1a802a82e01dcbf8b1
2025-09-29 07:08:24,423 - FacebookBot - INFO - [main.py:864] - ‚èπÔ∏è Bot stopped by user
2025-09-29 07:08:28,453 - urllib3.connectionpool - WARNING - [connectionpool.py:868] - Retrying (Retry(total=2, connect=None, read=None, redirect=None, status=None)) after connection broken by 'NewConnectionError('<urllib3.connection.HTTPConnection object at 0x000002189F6143E0>: Failed to establish a new connection: [WinError 10061] No connection could be made because the target machine actively refused it')': /session/53ac4d4a784d7d1a802a82e01dcbf8b1
2025-09-29 07:08:32,526 - urllib3.connectionpool - WARNING - [connectionpool.py:868] - Retrying (Retry(total=1, connect=None, read=None, redirect=None, status=None)) after connection broken by 'NewConnectionError('<urllib3.connection.HTTPConnection object at 0x000002189ED9A210>: Failed to establish a new connection: [WinError 10061] No connection could be made because the target machine actively refused it')': /session/53ac4d4a784d7d1a802a82e01dcbf8b1
2025-09-29 07:08:36,579 - urllib3.connectionpool - WARNING - [connectionpool.py:868] - Retrying (Retry(total=0, connect=None, read=None, redirect=None, status=None)) after connection broken by 'NewConnectionError('<urllib3.connection.HTTPConnection object at 0x000002189F618050>: Failed to establish a new connection: [WinError 10061] No connection could be made because the target machine actively refused it')': /session/53ac4d4a784d7d1a802a82e01dcbf8b1
